Workbook

Sheet air_pollution
A1: level_of_pollution | B1: region | C1: city | D1: impurity | E1: date | F1: time | G1: address | H1: concentration_(mg/m3) | I1: exceedance_factor | J1: wind_direction | K1: wind_speed | L1: temperature, C | M1: atmos_pressure_(mmHg) | N1: year
A2: Случаи высокого загрязнения (ВЗ) | B2: {=XLOOKUP(C2,city_to_region!$B$5:$B$96,city_to_region!$A$5:$A$96)} -> г. Астана | C2: г. Астана | D2: Сероводород | E2: 45556 | F2: 2:20 | G2: ПНЗ №8 (ул. Бабатайулы, д. 24 Коктал -1, средняя школа № 40 им. А.Маргулана) | H2: 0,0873 | I2: 10.9 | J2: 214 | K2: 0,0 | L2: 6,0 | M2: 731,4 | N2: 2024
A3: Случаи высокого загрязнения (ВЗ) | B3: {=XLOOKUP(C3,city_to_region!$B$5:$B$96,city_to_region!$A$5:$A$96)} -> г. Астана | C3: г. Астана | D3: Сероводород | E3: 45556 | F3: 2:40 | G3: ПНЗ №8 (ул. Бабатайулы, д. 24 Коктал -1, средняя школа № 40 им. А.Маргулана) | H3: 0,0901 | I3: 11.3 | J3: 210 | K3: 1,0 | L3: 5,0 | M3: 731,3 | N3: 2024
A4: Случаи высокого загрязнения (ВЗ) | B4: {=XLOOKUP(C4,city_to_region!$B$5:$B$96,city_to_region!$A$5:$A$96)} -> г. Астана | C4: г. Астана | D4: Сероводород | E4: 45566 | F4: 4:40 | G4: №10 Ул. К. Мунайтпасова, 13, Евразийский национальный университет им. Л.Н. Гумилева | H4: 0.0816 | I4: 10.2 | J4: 502 | K4: 0,0 | L4: 7,0 | M4: 738,9 | N4: 2024
A5: Случаи высокого загрязнения (ВЗ) | B5: {=XLOOKUP(C5,city_to_region!$B$5:$B$96,city_to_region!$A$5:$A$96)} -> Атырауская | C5: г. Атырау | D5: Сероводород | E5: 45373 | F5: 0:00 | G5: № 110 Привокзальный (ул. Еркинова) | H5: 0.0801 | I5: 10 | J5: 286 | K5: 0,7 | L5: 1,0 | M5: 765,4 | N5: 2024
A6: Случаи высокого загрязнения (ВЗ) | B6: {=XLOOKUP(C6,city_to_region!$B$5:$B$96,city_to_region!$A$5:$A$96)} -> Атырауская | C6: г. Атырау | D6: Сероводород | E6: 45376 | F6: 6:40 | G6: № 103 Шагала (ул. Смагулова) | H6: 0.1228 | I6: 15.4 | J6: 281 | K6: 0,5 | L6: 3,7 | M6: 761,1 | N6: 2024
A7: Случаи высокого загрязнения (ВЗ) | B7: {=XLOOKUP(C7,city_to_region!$B$5:$B$96,city_to_region!$A$5:$A$96)} -> Атырауская | C7: г. Атырау | D7: Сероводород | E7: 45376 | F7: 7:00 | G7: № 103 Шагала (ул. Смагулова) | H7: 0.1519 | I7: 19 | J7: 243 | K7: 0,7 | L7: 3,6 | M7: 761,2 | N7: 2024
A8: Случаи высокого загрязнения (ВЗ) | B8: {=XLOOKUP(C8,city_to_region!$B$5:$B$96,city_to_region!$A$5:$A$96)} -> Атырауская | C8: г. Атырау | D8: Сероводород | E8: 45376 | F8: 8:00 | G8: № 103 Шагала (ул. Смагулова) | H8: 0.0915 | I8: 11.4 | J8: 282 | K8: 0,8 | L8: 4,1 | M8: 761,4 | N8: 2024
A9: Случаи высокого загрязнения (ВЗ) | B9: {=XLOOKUP(C9,city_to_region!$B$5:$B$96,city_to_region!$A$5:$A$96)} -> Атырауская | C9: г. Атырау | D9: Сероводород | E9: 45376 | F9: 8:20 | G9: № 103 Шагала (ул. Смагулова) | H9: 0.087 | I9: 10.9 | J9: 302 | K9: 0,9 | L9: 4,3 | M9: 761,4 | N9: 2024
A10: Случаи высокого загрязнения (ВЗ) | B10: {=XLOOKUP(C10,city_to_region!$B$5:$B$96,city_to_region!$A$5:$A$96)} -> Атырауская | C10: г. Атырау | D10: Сероводород | E10: 45376 | F10: 3:00 | G10: № 109 Восток (ул. Махамбета, парк Курмангазы) | H10: 0.0939 | I10: 11.7 | J10: 281 | K10: 0,9 | L10: 5,9 | M10: 762,1 | N10: 2024
A11: Случаи высокого загрязнения (ВЗ) | B11: {=XLOOKUP(C11,city_to_region!$B$5:$B$96,city_to_region!$A$5:$A$96)} -> Атырауская | C11: г. Атырау | D11: Сероводород | E11: 45377 | F11: 3:20 | G11: № 109 Восток (ул. Махамбета, парк Курмангазы) | H11: 0.099 | I11: 12.4 | J11: 299 | K11: 0,7 | L11: 5,7 | M11: 762,0 | N11: 2024
A12: Случаи высокого загрязнения (ВЗ) | B12: {=XLOOKUP(C12,city_to_region!$B$5:$B$96,city_to_region!$A$5:$A$96)} -> Атырауская | C12: г. Атырау | D12: Сероводород | E12: 45378 | F12: 7:00 | G12: № 109 Восток (ул. Махамбета, парк Курмангазы) | H12: 0.1013 | I12: 12.7 | J12: 314 | K12: 0,7 | L12: 3,9 | M12: 761,4 | N12: 2024
A13: Случаи высокого загрязнения (ВЗ) | B13: {=XLOOKUP(C13,city_to_region!$B$5:$B$96,city_to_region!$A$5:$A$96)} -> Атырауская | C13: г. Атырау | D13: Сероводород | E13: 45379 | F13: 7:20 | G13: № 109 Восток (ул. Махамбета, парк Курмангазы) | H13: 0.1191 | I13: 14.9 | J13: 315 | K13: 1,0 | L13: 4,0 | M13: 761,4 | N13: 2024
A14: Случаи высокого загрязнения (ВЗ) | B14: {=XLOOKUP(C14,city_to_region!$B$5:$B$96,city_to_region!$A$5:$A$96)} -> Атырауская | C14: г. Атырау | D14: Сероводород | E14: 45380 | F14: 8:20 | G14: № 109 Восток (ул. Махамбета, парк Курмангазы) | H14: 0.1039 | I14: 13 | J14: 261 | K14: 1,4 | L14: 4,3 | M14: 761,5 | N14: 2024
A15: Случаи высокого загрязнения (ВЗ) | B15: {=XLOOKUP(C15,city_to_region!$B$5:$B$96,city_to_region!$A$5:$A$96)} -> Атырауская | C15: г. Атырау | D15: Сероводород | E15: 45381 | F15: 8:40 | G15: № 109 Восток (ул. Махамбета, парк Курмангазы) | H15: 0.0817 | I15: 10.2 | J15: 263 | K15: 1,2 | L15: 4,8 | M15: 761,5 | N15: 2024
... A52: Случаи высокого загрязнения (ВЗ) | B52: {=XLOOKUP(C52,city_to_region!$B$5:$B$96,city_to_region!$A$5:$A$96)} -> Атырауская | C52: г. Атырау | D52: Сероводород | E52: 45396 | F52: 7:40 | G52: № 111 Жилгородок (ул. Заполярная, дом Нефтяников) | H52: 0.0836 | I52: 10.5 | J52: 101 | K52: 0,7 | L52: 11,4 | M52: 759,4 | N52: 2024
A53: Случаи высокого загрязнения (ВЗ) | B53: {=XLOOKUP(C53,city_to_region!$B$5:$B$96,city_to_region!$A$5:$A$96)} -> Атырауская | C53: г. Атырау | D53: Сероводород | E53: 45409 | F53: 6:20 | G53: № 102 Самал (Макатский район, вахтовый поселок Самал) | H53: 0.0843 | I53: 10.5 | J53: 103 | K53: 6,0 | L53: 14,7 | M53: 769.1 | N53: 2024
A54: Случаи высокого загрязнения (ВЗ) | B54: {=XLOOKUP(C54,city_to_region!$B$5:$B$96,city_to_region!$A$5:$A$96)} -> Атырауская | C54: г. Атырау | D54: Сероводород | E54: 45409 | F54: 20:20 | G54: № 102 Самал (Макатский район, вахтовый поселок Самал) | H54: 0.1186 | I54: 14.8 | J54: 104 | K54: 2,8 | L54: 19,0 | M54: 769.9 | N54: 2024
A55: Случаи высокого загрязнения (ВЗ) | B55: {=XLOOKUP(C55,city_to_region!$B$5:$B$96,city_to_region!$A$5:$A$96)} -> Атырауская | C55: г. Атырау | D55: Сероводород | E55: 45409 | F55: 20:40 | G55: № 102 Самал (Макатский район, вахтовый поселок Самал) | H55: 0.1845 | I55: 23 | J55: 105 | K55: 2,4 | L55: 17,9 | M55: 769.9 | N55: 2024
A56: Случаи высокого загрязнения (ВЗ) | B56: {=XLOOKUP(C56,city_to_region!$B$5:$B$96,city_to_region!$A$5:$A$96)} -> Атырауская | C56: г. Атырау | D56: Сероводород | E56: 45409 | F56: 21:00 | G56: № 102 Самал (Макатский район, вахтовый поселок Самал) | H56: 0.1196 | I56: 14.9 | J56: 98 | K56: 2,7 | L56: 17,4 | M56: 770 | N56: 2024
A57: Случаи высокого загрязнения (ВЗ) | B57: {=XLOOKUP(C57,city_to_region!$B$5:$B$96,city_to_region!$A$5:$A$96)} -> Атырауская | C57: г. Атырау | D57: Сероводород | E57: 45411 | F57: 1:00 | G57: № 102 Самал (Макатский район, вахтовый поселок Самал) | H57: 0.128 | I57: 16 | J57: 101 | K57: 3,5 | L57: 13,4 | M57: 768 | N57: 2024
A58: Случаи высокого загрязнения (ВЗ) | B58: {=XLOOKUP(C58,city_to_region!$B$5:$B$96,city_to_region!$A$5:$A$96)} -> Атырауская | C58: г. Атырау | D58: Сероводород | E58: 45411 | F58: 1:20 | G58: № 102 Самал (Макатский район, вахтовый поселок Самал) | H58: 0.1411 | I58: 17.6 | J58: 106 | K58: 3,4 | L58: 13,4 | M58: 767.9 | N58: 2024
A59: Случаи высокого загрязнения (ВЗ) | B59: {=XLOOKUP(C59,city_to_region!$B$5:$B$96,city_to_region!$A$5:$A$96)} -> Атырауская | C59: г. Атырау | D59: Сероводород | E59: 45411 | F59: 3:40 | G59: № 102 Самал (Макатский район, вахтовый поселок Самал) | H59: 0.187 | I59: 23.3 | J59: 101 | K59: 3,2 | L59: 11,0 | M59: 767.8 | N59: 2024
A60: Случаи высокого загрязнения (ВЗ) | B60: {=XLOOKUP(C60,city_to_region!$B$5:$B$96,city_to_region!$A$5:$A$96)} -> Атырауская | C60: г. Атырау | D60: Сероводород | E60: 45411 | F60: 4:00 | G60: № 102 Самал (Макатский район, вахтовый поселок Самал) | H60: 0.1789 | I60: 22.3 | J60: 100 | K60: 3,2 | L60: 10,7 | M60: 767.8 | N60: 2024
A61: Случаи высокого загрязнения (ВЗ) | B61: {=XLOOKUP(C61,city_to_region!$B$5:$B$96,city_to_region!$A$5:$A$96)} -> Атырауская | C61: г. Атырау | D61: Сероводород | E61: 45411 | F61: 4:20 | G61: № 102 Самал (Макатский район, вахтовый поселок Самал) | H61: 0.1693 | I61: 21.1 | J61: 105 | K61: 3,2 | L61: 10,7 | M61: 767.8 | N61: 2024
A62: Случаи высокого загрязнения (ВЗ) | B62: {=XLOOKUP(C62,city_to_region!$B$5:$B$96,city_to_region!$A$5:$A$96)} -> Атырауская | C62: г. Атырау | D62: Сероводород | E62: 45419 | F62: 20:20 | G62: № 102 Самал (Макатский район, вахтовый поселок Самал) | H62: 0.0842 | I62: 10.5 | J62: 103 | K62: 4,8 | L62: 21,1 | M62: 760.4 | N62: 2024
A63: Случаи высокого загрязнения (ВЗ) | B63: {=XLOOKUP(C63,city_to_region!$B$5:$B$96,city_to_region!$A$5:$A$96)} -> Атырауская | C63: г. Атырау | D63: Сероводород | E63: 45419 | F63: 21:00 | G63: № 102 Самал (Макатский район, вахтовый поселок Самал) | H63: 0.0858 | I63: 10.7 | J63: 103 | K63: 4,0 | L63: 20,1 | M63: 760.3 | N63: 2024
A64: Случаи высокого загрязнения (ВЗ) | B64: {=XLOOKUP(C64,city_to_region!$B$5:$B$96,city_to_region!$A$5:$A$96)} -> Атырауская | C64: г. Атырау | D64: Сероводород | E64: 45423 | F64: 5:00 | G64: № 109 Восток (ул. Махамбета, парк Курмангазы) | H64: 0.0878 | I64: 11 | J64: 250 | K64: 0.39 | L64: 7,2 | M64: 766.7 | N64: 2024
A65: Случаи высокого загрязнения (ВЗ) | B65: {=XLOOKUP(C65,city_to_region!$B$5:$B$96,city_to_region!$A$5:$A$96)} -> Атырауская | C65: г. Атырау | D65: Сероводород | E65: 45423 | F65: 5:20 | G65: № 109 Восток (ул. Махамбета, парк Курмангазы) | H65: 0.0811 | I65: 10.1 | J65: 155 | K65: 0.39 | L65: 7,0 | M65: 766.6 | N65: 2024
A66: Случаи высокого загрязнения (ВЗ) | B66: {=XLOOKUP(C66,city_to_region!$B$5:$B$96,city_to_region!$A$5:$A$96)} -> Атырауская | C66: г. Атырау | D66: Сероводород | E66: 45442 | F66: 2:20 | G66: № 102 Самал (Вахтовый поселок Самал) | H66: 0,0975 | I66: 12.2 | J66: 100 | K66: 2,8 | L66: 17,0 | M66: 764,1 | N66: 2024
A67: Случаи высокого загрязнения (ВЗ) | B67: {=XLOOKUP(C67,city_to_region!$B$5:$B$96,city_to_region!$A$5:$A$96)} -> Атырауская | C67: г. Атырау | D67: Сероводород | E67: 45442 | F67: 2:40 | G67: № 102 Самал (Вахтовый поселок Самал) | H67: 0,2628 | I67: 32.8 | J67: 97 | K67: 3,1 | L67: 16,9 | M67: 764,1 | N67: 2024
A68: Случаи высокого загрязнения (ВЗ) | B68: {=XLOOKUP(C68,city_to_region!$B$5:$B$96,city_to_region!$A$5:$A$96)} -> Атырауская | C68: г. Атырау | D68: Сероводород | E68: 45442 | F68: 3:00 | G68: № 102 Самал (Вахтовый поселок Самал) | H68: 0,1256 | I68: 15.7 | J68: 96 | K68: 3,2 | L68: 17,0 | M68: 764,0 | N68: 2024
A69: Случаи высокого загрязнения (ВЗ) | B69: {=XLOOKUP(C69,city_to_region!$B$5:$B$96,city_to_region!$A$5:$A$96)} -> Атырауская | C69: г. Атырау | D69: Сероводород | E69: 45442 | F69: 3:20 | G69: № 102 Самал (Вахтовый поселок Самал) | H69: 0,1686 | I69: 21.1 | J69: 103 | K69: 2,9 | L69: 17,3 | M69: 764,1 | N69: 2024
A70: Случаи высокого загрязнения (ВЗ) | B70: {=XLOOKUP(C70,city_to_region!$B$5:$B$96,city_to_region!$A$5:$A$96)} -> Атырауская | C70: г. Атырау | D70: Сероводород | E70: 45442 | F70: 3:40 | G70: № 102 Самал (Вахтовый поселок Самал) | H70: 0,1802 | I70: 22.5 | J70: 102 | K70: 3,3 | L70: 17,9 | M70: 764,1 | N70: 2024
A71: Случаи высокого загрязнения (ВЗ) | B71: {=XLOOKUP(C71,city_to_region!$B$5:$B$96,city_to_region!$A$5:$A$96)} -> Атырауская | C71: г. Атырау | D71: Сероводород | E71: 45442 | F71: 4:00 | G71: № 102 Самал (Вахтовый поселок Самал) | H71: 0,1347 | I71: 16.8 | J71: 104 | K71: 3,3 | L71: 18,7 | M71: 764,2 | N71: 2024
A72: Случаи высокого загрязнения (ВЗ) | B72: {=XLOOKUP(C72,city_to_region!$B$5:$B$96,city_to_region!$A$5:$A$96)} -> Атырауская | C72: г. Атырау | D72: Сероводород | E72: 45442 | F72: 4:20 | G72: № 102 Самал (Вахтовый поселок Самал) | H72: 0,1056 | I72: 13.2 | J72: 101 | K72: 3,2 | L72: 18,7 | M72: 764,2 | N72: 2024
A73: Случаи высокого загрязнения (ВЗ) | B73: {=XLOOKUP(C73,city_to_region!$B$5:$B$96,city_to_region!$A$5:$A$96)} -> Атырауская | C73: г. Атырау | D73: Сероводород | E73: 45442 | F73: 4:40 | G73: № 102 Самал (Вахтовый поселок Самал) | H73: 0,1891 | I73: 23.6 | J73: 103 | K73: 2,7 | L73: 18,4 | M73: 764,2 | N73: 2024
A74: Случаи высокого загрязнения (ВЗ) | B74: {=XLOOKUP(C74,city_to_region!$B$5:$B$96,city_to_region!$A$5:$A$96)} -> Атырауская | C74: г. Атырау | D74: Сероводород | E74: 45442 | F74: 5:00 | G74: № 102 Самал (Вахтовый поселок Самал) | H74: 0,1363 | I74: 17 | J74: 107 | K74: 2,7 | L74: 18,1 | M74: 764,3 | N74: 2024
A75: Случаи высокого загрязнения (ВЗ) | B75: {=XLOOKUP(C75,city_to_region!$B$5:$B$96,city_to_region!$A$5:$A$96)} -> Атырауская | C75: г. Атырау | D75: Сероводород | E75: 45442 | F75: 5:40 | G75: № 102 Самал (Вахтовый поселок Самал) | H75: 0,1740 | I75: 21.7 | J75: 92 | K75: 2,5 | L75: 17,1 | M75: 764,3 | N75: 2024
A76: Случаи высокого загрязнения (ВЗ) | B76: {=XLOOKUP(C76,city_to_region!$B$5:$B$96,city_to_region!$A$5:$A$96)} -> Атырауская | C76: г. Атырау | D76: Сероводород | E76: 45442 | F76: 3:00 | G76: № 117 Карабатан (Железнодорожная станция Карабатан) | H76: 0,0986 | I76: 12.3 | J76: 109 | K76: 3,5 | L76: 19,2 | M76: 764,8 | N76: 2024
...

Sheet air_anti_leaders_from_measureme
A1: region | B1: COUNTA из level_of_pollution | C1: MEDIAN из exceedance_factor | D1: MAX из exceedance_factor
A2: г. Шымкент | B2: 0.046511628 | C2: 51.4 | D2: 185.8
A3: Атырауская | B3: 0.50317125 | C3: 15.4 | D3: 87.1
A4: Актюбинская | B4: 0.023255814 | C4: 12.3 | D4: 21.3
A5: Карагандинская | B5: 0.41860465 | C5: 12.1 | D5: 26.6
A6: г. Астана | B6: 0.0063424947 | C6: 10.9 | D6: 11.3
A7: Область Улытау | B7: 0.0021141649 | C7: 10 | D7: 10
A10: Таблица показывает процентное соотношение количества взятия проб качества воздуха в регионах в 2024 году (ст. B). Примечательно, что содержание вредных примесей в воздухе стабильно измеряется только в этих субъектах.
A11: Также в ней проиллюстрировано медианное значение превышения предельной нормы концентрации вредных веществ в воздухе (ст. C).
A12: Помимо этого представлена информация по максимальному показателю превышения допустимой нормы (ст. D)

Sheet metadata_air_pollution
B1: Сведения о случаях высокого загрязнения и экстремально высокого загрязнения атмосферного воздуха Республики Казахстан за 2024 год
A3: № | B3: Наименование в таблице | C3: Значение
A4: 1 | B4: level_of_pollution | C4: уровень загрязнения
A5: 2 | B5: region | C5: область
A6: 3 | B6: city | C6: город
A7: 4 | B7: impurity | C7: примесь
A8: 5 | B8: date | C8: дата загрязнения
A9: 6 | B9: time | C9: время измерения показателей загрязнения
A10: 7 | B10: address | C10: адрес, где было произведено измерение
A11: 8 | B11: concentration_(mg/m3) | C11: концентрация примеси (мг/м3)
A12: 9 | B12: exceedance_factor | C12: кратность превышения
A13: 10 | B13: wind_direction | C13: направление ветра в градусах
A14: 11 | B14: wind_speed | C14: скорость ветра
A15: 12 | B15: temperature, C | C15: температура в момент измерения
... A17: 14 | B17: year | C17: год

Sheet air_pollution_index
A1: region | B1: city | C1: air_index
A2: {=XLOOKUP(B2,city_to_region!$B$5:$B$96,city_to_region!$A$5:$A$96)} -> г. Астана | B2: г. Астана | C2: 11.5
A3: {=XLOOKUP(B3,city_to_region!$B$5:$B$96,city_to_region!$A$5:$A$96)} -> Карагандинская | B3: г. Темиртау | C3: 10.2
A4: {=XLOOKUP(B4,city_to_region!$B$5:$B$96,city_to_region!$A$5:$A$96)} -> Восточно-Казахстанская | B4: г. Усть-Каменогорск | C4: 8.2
A5: {=XLOOKUP(B5,city_to_region!$B$5:$B$96,city_to_region!$A$5:$A$96)} -> г. Шымкент | B5: г. Шымкент | C5: 7.5
A6: {=XLOOKUP(B6,city_to_region!$B$5:$B$96,city_to_region!$A$5:$A$96)} -> Область Улытау | B6: г. Жезказган | C6: 6.8
A7: {=XLOOKUP(B7,city_to_region!$B$5:$B$96,city_to_region!$A$5:$A$96)} -> Акмолинская | B7: пос. Бурабай | C7: 6.5
A8: {=XLOOKUP(B8,city_to_region!$B$5:$B$96,city_to_region!$A$5:$A$96)} -> Акмолинская | B8: пос. Бестобе | C8: 6.3
A9: {=XLOOKUP(B9,city_to_region!$B$5:$B$96,city_to_region!$A$5:$A$96)} -> г. Алматы | B9: г. Алматы | C9: 6
A10: {=XLOOKUP(B10,city_to_region!$B$5:$B$96,city_to_region!$A$5:$A$96)} -> Туркестанская | B10: г. Туркестан | C10: 5.2
A11: {=XLOOKUP(B11,city_to_region!$B$5:$B$96,city_to_region!$A$5:$A$96)} -> Костанайская | B11: г. Костанай | C11: 5
A12: {=XLOOKUP(B12,city_to_region!$B$5:$B$96,city_to_region!$A$5:$A$96)} -> Жамбылская | B12: г. Тараз | C12: 4.7
A13: {=XLOOKUP(B13,city_to_region!$B$5:$B$96,city_to_region!$A$5:$A$96)} -> Мангыстауская | B13: г. Актау | C13: 4.2
... A50: {=XLOOKUP(B50,city_to_region!$B$5:$B$96,city_to_region!$A$5:$A$96)} -> Кызылординская | B50: с. Шиели | C50: 0.3
A51: {=XLOOKUP(B51,city_to_region!$B$2:$B$96,city_to_region!$A$2:$A$96)} -> Область Абай | B51: г. Аягоз | C51: 0.3
A52: {=XLOOKUP(B52,city_to_region!$B$5:$B$96,city_to_region!$A$5:$A$96)} -> Область Улытау | B52: г. Сатпаев | C52: 0.2
A53: {=XLOOKUP(B53,city_to_region!$B$5:$B$96,city_to_region!$A$5:$A$96)} -> Актюбинская | B53: с. Кенкияк | C53: 0.2
A54: {=XLOOKUP(B54,city_to_region!$B$5:$B$96,city_to_region!$A$5:$A$96)} -> Атырауская | B54: с. Жанбай | C54: 0.2
A55: {=XLOOKUP(B55,city_to_region!$B$5:$B$96,city_to_region!$A$5:$A$96)} -> Актюбинская | B55: г. Кандыагаш | C55: 0.2
A56: {=XLOOKUP(B56,city_to_region!$B$2:$B$96,city_to_region!$A$2:$A$96)} -> Область Абай | B56: г. Абай | C56: 0.1
A57: {=XLOOKUP(B57,city_to_region!$B$5:$B$96,city_to_region!$A$5:$A$96)} -> Атырауская | B57: с. Ганюшкино | C57: 0.1
A58: {=XLOOKUP(B58,city_to_region!$B$5:$B$96,city_to_region!$A$5:$A$96)} -> Западно-Казахстанская | B58: с. Бурлин | C58: 0.1
A59: {=XLOOKUP(B59,city_to_region!$B$5:$B$96,city_to_region!$A$5:$A$96)} -> Костанайская | B59: пос. Карабалык | C59: 0.1
A60: {=XLOOKUP(B60,city_to_region!$B$5:$B$96,city_to_region!$A$5:$A$96)} -> Атырауская | B60: пос. Индерборский | C60: 0.1
A61: {=XLOOKUP(B61,city_to_region!$B$5:$B$96,city_to_region!$A$5:$A$96)} -> Костанайская | B61: г. Аркалык | C61: 0.1
A62: {=XLOOKUP(B62,city_to_region!$B$5:$B$96,city_to_region!$A$5:$A$96)} -> Восточно-Казахстанская | B62: г. Шемонаиха | C62: 0.1
A63: {=XLOOKUP(B63,city_to_region!$B$5:$B$96,city_to_region!$A$5:$A$96)} -> Кызылординская | B63: пос. Айтеке би | C63: 0.1
A64: {=XLOOKUP(B64,city_to_region!$B$5:$B$96,city_to_region!$A$5:$A$96)} -> Жамбылская | B64: г. Каратау | C64: 0.1
A65: {=XLOOKUP(B65,city_to_region!$B$5:$B$96,city_to_region!$A$5:$A$96)} -> Кызылординская | B65: г. Аральск | C65: 0.1
A66: {=XLOOKUP(B66,city_to_region!$B$5:$B$96,city_to_region!$A$5:$A$96)} -> Карагандинская | B66: г. Сарань | C66: 0.1
A67: {=XLOOKUP(B67,city_to_region!$B$2:$B$96,city_to_region!$A$2:$A$96)} -> Область Абай | B67: пос. Ауэзов | C67: 0.1
A68: {=XLOOKUP(B68,city_to_region!$B$5:$B$96,city_to_region!$A$5:$A$96)} -> Мангыстауская | B68: г. Жанаозен | C68: 0.1
A69: {=XLOOKUP(B69,city_to_region!$B$5:$B$96,city_to_region!$A$5:$A$96)} -> Туркестанская | B69: пос. Састобе | C69: 0.1
A70: {=XLOOKUP(B70,city_to_region!$B$5:$B$96,city_to_region!$A$5:$A$96)} -> Туркестанская | B70: г. Кентау | C70: 0.1
A71: {=XLOOKUP(B71,city_to_region!$B$5:$B$96,city_to_region!$A$5:$A$96)} -> Акмолинская | B71: г. Атбасар | C71: 0.1

Sheet air_index_anti_leaders
A1: region | B1: MEDIAN из air_index | D1: region | E1: MEDIAN из air_index
A2: г. Астана | B2: 11.5 | D2: г. Астана | E2: 11.5
A3: г. Шымкент | B3: 7.5 | D3: г. Шымкент | E3: 7.5
A4: г. Алматы | B4: 6 | D4: г. Алматы | E4: 6
A5: Северо-Казахстанская | B5: 3.8 | D5: Северо-Казахстанская | E5: 3.8
A6: Область Улытау | B6: 3.5 | D6: Область Улытау | E6: 3.5
A7: Жамбылская | B7: 2.9
A8: Восточно-Казахстанская | B8: 2.8
A9: Карагандинская | B9: 2.3 | D9: Регионы-антилидеры по ИЗА (Индекс загрязнения атмосферы, показывает уровень хронического, длительного загрязнения воздуха).
A10: Акмолинская | B10: 2.15
A11: Мангыстауская | B11: 2 | D11: *Для наглядности
A12: Область Жетысу | B12: 1.9 | D12: region | E12: COUNTA из level_of_pollution | F12: MEDIAN из exceedance_factor | G12: MAX из exceedance_factor
A13: Павлодарская | B13: 1.8 | D13: г. Шымкент | E13: 0.046511628 | F13: 51.4 | G13: 185.8
A14: Алматинская | B14: 0.9 | D14: Атырауская | E14: 0.50317125 | F14: 15.4 | G14: 87.1
A15: Костанайская | B15: 0.85 | D15: Актюбинская | E15: 0.023255814 | F15: 12.3 | G15: 21.3
A16: Кызылординская | B16: 0.8 | D16: Карагандинская | E16: 0.41860465 | F16: 12.1 | G16: 26.6
A17: Актюбинская | B17: 0.4 | D17: г. Астана | E17: 0.0063424947 | F17: 10.9 | G17: 11.3
A18: Западно-Казахстанская | B18: 0.3 | D18: Область Улытау | E18: 0.0021141649 | F18: 10 | G18: 10
A19: Атырауская | B19: 0.3
A20: Область Абай | B20: 0.2 | D20: Если сравнить таблицы по ИЗА и таблице с регионами, где постоянно собирают пробы качества воздуха, встают вопросы:
A21: Туркестанская | B21: 0.1 | D21: Почему в г. Астана так редко берут пробы воздуха, если она явно лидирует по ИЗА?
D22: Почему пробы по г. Алматы и Северо-Казахстанской области вообще не представлены?
D23: С чем в таком случае связаны высокие показатели ИЗА, если в таблице с выбросами информации по этим регионам нет?

Sheet metadata_air_pollution_index 
B1: Уровень загрязнения населенных пунктов Республики Казахстан (индекс загрязнения атмосферы) за 2024 год
A3: № | B3: Наименование в таблице | C3: Значение
A4: 1 | B4: region | C4: область
A5: 2 | B5: city | C5: город / населённый пункт
A6: 3 | B6: air_index | C6: ИЗА (показатель)

Sheet water_pollution
A1: region | B1: city | C1: water_body | D1: HPE_EHE | E1: date | F1: date_analysis | G1: substance_name | H1: unit_measure | I1: concentration | J1: year
A2: {=XLOOKUP(B2, city_to_region!$B$5:$B$96, city_to_region!$A$5:$A$96)} -> г. Астана | B2: г. Астана | C2: река Акбулак, 0,5 км выше выпуска промывных вод насосно-фильтровальной станции (район ул. Ш. Кудайбердиева) | D2: 1 ЭВЗ | E2: 45300 | F2: 45301 | G2: Растворенный кислород | H2: мг/дм3 | I2: 1.14 | J2: 2024
A3: {=XLOOKUP(B3, city_to_region!$B$5:$B$96, city_to_region!$A$5:$A$96)} -> г. Астана | B3: г. Астана | C3: река Акбулак, 0,5 км выше выпуска промывных вод насосно-фильтровальной станции (район ул. Ш. Кудайбердиева) | D3: 1 ЭВЗ | E3: 45327 | F3: 45328 | G3: Растворенный кислород | H3: мг/дм3 | I3: 1.37 | J3: 2024
A4: {=XLOOKUP(B4, city_to_region!$B$5:$B$96, city_to_region!$A$5:$A$96)} -> г. Астана | B4: г. Астана | C4: река Акбулак, 0,5 км выше выпуска промывных вод насосно-фильтровальной станции (район ул. Ш. Кудайбердиева) | D4: 1 ВЗ | E4: 45356 | F4: 45356 | G4: Растворенный кислород | H4: мг/дм3 | I4: 2.29 | J4: 2024
A5: {=XLOOKUP(B5, city_to_region!$B$5:$B$96, city_to_region!$A$5:$A$96)} -> г. Астана | B5: г. Астана | C5: река Акбулак, 0,5 км выше выпуска промывных вод насосно-фильтровальной станции (район ул. Ш. Кудайбердиева) | D5: 1 ЭВЗ | E5: 45464 | F5: 45464 | G5: Растворенный кислород | H5: мг/дм3 | I5: 0 | J5: 2024
A6: {=XLOOKUP(B6, city_to_region!$B$5:$B$96, city_to_region!$A$5:$A$96)} -> г. Астана | B6: г. Астана | C6: река Акбулак, 0,5 км выше выпуска промывных вод насосно-фильтровальной станции (район ул. Ш. Кудайбердиева) | D6: 1 ЭВЗ | E6: 45484 | F6: 45484 | G6: Растворенный кислород | H6: мг/дм3 | I6: 0 | J6: 2024
A7: {=XLOOKUP(B7, city_to_region!$B$5:$B$96, city_to_region!$A$5:$A$96)} -> г. Астана | B7: г. Астана | C7: река Акбулак, 0,5 км выше выпуска промывных вод насосно-фильтровальной станции (район ул. Ш. Кудайбердиева) | D7: 1 ЭВЗ | E7: 45511 | F7: 45511 | G7: Растворенный кислород | H7: мг/дм3 | I7: 0 | J7: 2024
A8: {=XLOOKUP(B8, city_to_region!$B$5:$B$96, city_to_region!$A$5:$A$96)} -> г. Астана | B8: г. Астана | C8: река Акбулак, 0,5 км ниже выпуска промывных вод насосно-фильтровальной станции (район ул. Ш. Кудайбердиева) | D8: 1 ЭВЗ | E8: 45484 | F8: 45484 | G8: Растворенный кислород | H8: мг/дм3 | I8: 0 | J8: 2024
A9: {=XLOOKUP(B9, city_to_region!$B$5:$B$96, city_to_region!$A$5:$A$96)} -> г. Астана | B9: г. Астана | C9: река Акбулак, 0,5 км ниже выпуска промывных вод насосно-фильтровальной станции (район ул. Ш. Кудайбердиева) | D9: 1 ВЗ | E9: 45544 | F9: 45544 | G9: Растворенный кислород | H9: мг/дм3 | I9: 2.28 | J9: 2024
A10: {=XLOOKUP(B10, city_to_region!$B$5:$B$96, city_to_region!$A$5:$A$96)} -> г. Астана | B10: г. Астана | C10: река Акбулак, 0,5 км выше выпуска очищенных ливневых вод, район ул. Акжол | D10: 1 ЭВЗ | E10: 45300 | F10: 45301 | G10: Растворенный кислород | H10: мг/дм3 | I10: 0.92 | J10: 2024
A11: {=XLOOKUP(B11, city_to_region!$B$5:$B$96, city_to_region!$A$5:$A$96)} -> г. Астана | B11: г. Астана | C11: река Акбулак, 0,5 км выше выпуска очищенных ливневых вод, район ул. Акжол | D11: 1 ЭВЗ | E11: 45511 | F11: 45511 | G11: Растворенный кислород | H11: мг/дм3 | I11: 1.34 | J11: 2024
A12: {=XLOOKUP(B12, city_to_region!$B$5:$B$96, city_to_region!$A$5:$A$96)} -> г. Астана | B12: г. Астана | C12: река Акбулак, 0,5 км выше выпуска очищенных ливневых вод, район ул. Акжол | D12: 1 ВЗ | E12: 45544 | F12: 45544 | G12: Растворенный кислород | H12: мг/дм3 | I12: 2.81 | J12: 2024
A13: {=XLOOKUP(B13, city_to_region!$B$5:$B$96, city_to_region!$A$5:$A$96)} -> г. Астана | B13: г. Астана | C13: река Акбулак, 0,5 км ниже выпуска очищенных ливневых вод, район ул. Акжол | D13: 1 ЭВЗ | E13: 45300 | F13: 45301 | G13: Растворенный кислород | H13: мг/дм3 | I13: 1.6 | J13: 2024
... A78: {=XLOOKUP(B78, city_to_region!$B$5:$B$96, city_to_region!$A$5:$A$96)} -> Карагандинская | B78: г. Темиртау | C78: река Нура, 0,1 км ниже г. Темиртау, 1 км выше объединенного сброса сточных вод АО «АрселорМиттал Темиртау» и АО «ТЭМК» | D78: 1 ВЗ | E78: 45384 | F78: 45387 | G78: Железо общее | H78: мг/дм3 | I78: 0.72 | J78: 2024
A79: {=XLOOKUP(B79, city_to_region!$B$5:$B$96, city_to_region!$A$5:$A$96)} -> Карагандинская | B79: г. Темиртау | C79: река Нура, 0,1 км ниже г. Темиртау, 1 км выше объединенного сброса сточных вод АО «АрселорМиттал Темиртау» и АО «ТЭМК» | D79: 1 ВЗ | E79: 45390 | F79: 12.04.20224 | G79: Железо общее | H79: мг/дм3 | I79: 0.69 | J79: 2024
A80: {=XLOOKUP(B80, city_to_region!$B$5:$B$96, city_to_region!$A$5:$A$96)} -> Карагандинская | B80: г. Темиртау | C80: река Нура, 0,1 км ниже г. Темиртау, 1 км выше объединенного сброса сточных вод АО «АрселорМиттал Темиртау» и АО «ТЭМК» | D80: 1 ВЗ | E80: 45399 | F80: 45404 | G80: Жеклезо общее | H80: мг/дм3 | I80: 0.54 | J80: 2024
A81: {=XLOOKUP(B81, city_to_region!$B$5:$B$96, city_to_region!$A$5:$A$96)} -> Карагандинская | B81: г. Темиртау | C81: река Нура, 0,1 км ниже г. Темиртау, 1 км выше объединенного сброса сточных вод АО «АрселорМиттал Темиртау» и АО «ТЭМК» | D81: 1 ВЗ | E81: 45483 | F81: 45485 | G81: Марганец | H81: мг/дм3 | I81: 0.131 | J81: 2024
A82: {=XLOOKUP(B82, city_to_region!$B$5:$B$96, city_to_region!$A$5:$A$96)} -> Карагандинская | B82: г. Темиртау | C82: река Нура, 0,1 км ниже г. Темиртау, 1 км выше объединенного сброса сточных вод АО «АрселорМиттал Темиртау» и АО «ТЭМК» | D82: 1 ВЗ | E82: 45483 | F82: 45485 | G82: Железо общее | H82: мг/дм3 | I82: 0.45 | J82: 2024
A83: {=XLOOKUP(B83, city_to_region!$B$5:$B$96, city_to_region!$A$5:$A$96)} -> Карагандинская | B83: г. Темиртау | C83: река Нура, г. Темиртау, 2,1 ниже г. Темиртау, 1 км ниже объединенного сброса сточных вод АО «АрселорМиттал Темиртау» и АО «ТЭМК» | D83: 1 ВЗ | E83: 45384 | F83: 45387 | G83: Железо общее | H83: мг/дм3 | I83: 0.77 | J83: 2024
A84: {=XLOOKUP(B84, city_to_region!$B$5:$B$96, city_to_region!$A$5:$A$96)} -> Карагандинская | B84: г. Темиртау | C84: река Нура, г. Темиртау, 2,1 ниже г. Темиртау, 1 км ниже объединенного сброса сточных вод АО «АрселорМиттал Темиртау» и АО «ТЭМК» | D84: 1 ВЗ | E84: 45390 | F84: 45394 | G84: Железо общее | H84: мг/дм3 | I84: 0.78 | J84: 2024
A85: {=XLOOKUP(B85, city_to_region!$B$5:$B$96, city_to_region!$A$5:$A$96)} -> Карагандинская | B85: г. Темиртау | C85: река Нура, г. Темиртау, 2,1 ниже г. Темиртау, 1 км ниже объединенного сброса сточных вод АО «АрселорМиттал Темиртау» и АО «ТЭМК» | D85: 1 ВЗ | E85: 45399 | F85: 45404 | G85: Железо общее | H85: мг/дм3 | I85: 0.49 | J85: 2024
A86: {=XLOOKUP(B86, city_to_region!$B$5:$B$96, city_to_region!$A$5:$A$96)} -> Карагандинская | B86: г. Темиртау | C86: река Нура, г. Темиртау, 2,1 ниже г. Темиртау, 1 км ниже объединенного сброса сточных вод АО «АрселорМиттал Темиртау» и АО «ТЭМК» | D86: 1 ВЗ | E86: 45427 | F86: 45428 | G86: Железо общее | H86: мг/дм3 | I86: 0.53 | J86: 2024
A87: {=XLOOKUP(B87, city_to_region!$B$5:$B$96, city_to_region!$A$5:$A$96)} -> Карагандинская | B87: г. Темиртау | C87: река Нура, г. Темиртау, 2,1 ниже г. Темиртау, 1 км ниже объединенного сброса сточных вод АО «АрселорМиттал Темиртау» и АО «ТЭМК» | D87: 1 ВЗ | E87: 45483 | F87: 45485 | G87: Марганец | H87: мг/дм3 | I87: 0.152 | J87: 2024
A88: {=XLOOKUP(B88, city_to_region!$B$5:$B$96, city_to_region!$A$5:$A$96)} -> Карагандинская | B88: г. Темиртау | C88: река Нура, г. Темиртау, 2,1 ниже г. Темиртау, 1 км ниже объединенного сброса сточных вод АО «АрселорМиттал Темиртау» и АО «ТЭМК» | D88: 1 ВЗ | E88: 45483 | F88: 45485 | G88: Железо общее | H88: мг/дм3 | I88: 0.42 | J88: 2024
A89: {=XLOOKUP(B89, city_to_region!$B$5:$B$96, city_to_region!$A$5:$A$96)} -> Карагандинская | B89: г. Темиртау | C89: река Нура, г.Темиртау, 6,8 км ниже г.Темиртау, 5,7 км ниже объединенного сброса сточных вод АО «АрселорМиттал Темиртау» и АО «ТЭМК» | D89: 1 ВЗ | E89: 45384 | F89: 45387 | G89: Железо общее | H89: мг/дм3 | I89: 0.77 | J89: 2024
A90: {=XLOOKUP(B90, city_to_region!$B$5:$B$96, city_to_region!$A$5:$A$96)} -> Карагандинская | B90: г. Темиртау | C90: река Нура, г.Темиртау, 6,8 км ниже г.Темиртау, 5,7 км ниже объединенного сброса сточных вод АО «АрселорМиттал Темиртау» и АО «ТЭМК» | D90: 1 ВЗ | E90: 45390 | F90: 45394 | G90: Железо общее | H90: мг/дм3 | I90: 0.9 | J90: 2024
A91: {=XLOOKUP(B91, city_to_region!$B$5:$B$96, city_to_region!$A$5:$A$96)} -> Карагандинская | B91: г. Темиртау | C91: река Нура, г.Темиртау, 6,8 км ниже г.Темиртау, 5,7 км ниже объединенного сброса сточных вод АО «АрселорМиттал Темиртау» и АО «ТЭМК» | D91: 1 ВЗ | E91: 45399 | F91: 45404 | G91: Железо общее | H91: мг/дм3 | I91: 0.55 | J91: 2024
... A217: {=XLOOKUP(B217, city_to_region!$B$5:$B$96, city_to_region!$A$5:$A$96)} -> г. Астана | B217: г. Астана | C217: река Акбулак, г. Астана, 0,5 км ниже выпуска очищенных ливневых вод, район ул. Акжол | D217: Для сведения | E217: 45544 | F217: 45544 | G217: Сероводород | H217: мг/дм3 | I217: 0.049 | J217: 2024

Sheet water_anti_leaders
A1: region | B1: COUNTA из HPE_EHE
A2: Карагандинская | B2: 73
A3: Костанайская | B3: 54
A4: Восточно-Казахстанская | B4: 30
A5: г. Астана | B5: 29
A6: Область Улытау | B6: 19
A7: Акмолинская | B7: 7
A8: Северо-Казахстанская | B8: 4
A10: Количество случаев высокого и экстремально выского загрязнения поверхностных вод регионов в 2024 году.
A11: Стоит подчеркнуть, что в исходной таблице представлены данные по водным ресурсам только этих областей.

Sheet water_impurities
F3: Здесь представлены вредные примеси, которые чаще всего встречаются
F4: в водах трех регионов, "возглавляющих" рейтинг.

Sheet soil_pollution
A1: region | B1: city | C1: exceedance_MPC | D1: year
A2: {=XLOOKUP(B2, city_to_region!$B$5:$B$96, city_to_region!$A$5:$A$96)} -> Карагандинская | B2: г. Темиртау | C2: 8.02 | D2: 2024
A3: {=XLOOKUP(B3, city_to_region!$B$5:$B$96, city_to_region!$A$5:$A$96)} -> Карагандинская | B3: г. Балхаш | C3: 17.9 | D3: 2024
A4: {=XLOOKUP(B4, city_to_region!$B$5:$B$96, city_to_region!$A$5:$A$96)} -> Область Улытау | B4: г. Жезказган | C4: 18.3 | D4: 2024
A5: {=XLOOKUP(B5, city_to_region!$B$5:$B$96, city_to_region!$A$5:$A$96)} -> г. Алматы | B5: г. Алматы | C5: 2.4 | D5: 2024
A6: {=XLOOKUP(B6, city_to_region!$B$5:$B$96, city_to_region!$A$5:$A$96)} -> Восточно-Казахстанская | B6: г. Усть-Каменогорск | C6: 6.96 | D6: 2024
A7: {=XLOOKUP(B7, city_to_region!$B$5:$B$96, city_to_region!$A$5:$A$96)} -> Восточно-Казахстанская | B7: г. Риддер | C7: 2.5 | D7: 2024
A8: {=XLOOKUP(B8, city_to_region!$B$5:$B$96, city_to_region!$A$5:$A$96)} -> Восточно-Казахстанская | B8: г. Риддер | C8: 40.7 | D8: 2024
A9: {=XLOOKUP(B9, city_to_region!$B$5:$B$96, city_to_region!$A$5:$A$96)} -> Область Абай | B9: г. Семей | C9: 2.23 | D9: 2024
A10: {=XLOOKUP(B10, city_to_region!$B$5:$B$96, city_to_region!$A$5:$A$96)} -> Кызылординская | B10: г. Кызылорда | C10: 1.16 | D10: 2024
A11: {=XLOOKUP(B11, city_to_region!$B$5:$B$96, city_to_region!$A$5:$A$96)} -> Кызылординская | B11: пос. Куланды | C11: 5.75 | D11: 2024
A12: {=XLOOKUP(B12, city_to_region!$B$5:$B$96, city_to_region!$A$5:$A$96)} -> Область Жетысу | B12: г. Талдыкорган | C12: 2.21 | D12: 2024
A13: {=XLOOKUP(B13, city_to_region!$B$5:$B$96, city_to_region!$A$5:$A$96)} -> Область Жетысу | B13: г. Талдыкорган | C13: 15.5 | D13: 2024
... A28: {=XLOOKUP(B28, city_to_region!$B$5:$B$96, city_to_region!$A$5:$A$96)} -> Костанайская | B28: г. Лисаковск | C28: 1.03 | D28: 2024

Sheet soil_anti_leaders
A1: region | B1: MEDIAN из exceedance_MPC | E1: region | F1: MAX из exceedance_MPC
A2: Область Улытау | B2: 18.3 | E2: Восточно-Казахстанская | F2: 40.7
A3: Карагандинская | B3: 12.96 | E3: Область Улытау | F3: 18.3
A4: Восточно-Казахстанская | B4: 6.96 | E4: Карагандинская | F4: 17.9
A5: Кызылординская | B5: 3.455 | E5: Область Жетысу | F5: 15.5
A6: Область Жетысу | B6: 2.63 | E6: Кызылординская | F6: 5.75
A7: г. Алматы | B7: 2.4 | E7: г. Алматы | F7: 2.4
A8: Область Абай | B8: 2.23 | E8: Область Абай | F8: 2.23
A9: Жамбылская | B9: 1.675 | E9: Жамбылская | F9: 1.95
A10: Туркестанская | B10: 1.35 | E10: Туркестанская | F10: 1.5
A11: Павлодарская | B11: 1.25 | E11: Павлодарская | F11: 1.4
A12: г. Шымкент | B12: 1.14 | E12: Костанайская | F12: 1.37
A13: Костанайская | B13: 1.05 | E13: г. Шымкент | F13: 1.14
A14: Северо-Казахстанская | B14: 1.01 | E14: Северо-Казахстанская | F14: 1.01
A16: Показано медианное значение показателя превышения предельно допустимой нормы содержания свинца и хрома в почвах областей.
A17: Дополнительно приведена таблица с максимальными значениями данного показателя.
A18: Можно заметить, что по медиане Восточно-Казахстанская область находится на третьем месте и имеет невысокий показатель,
A19: однако она явно лидирует по максимальному значению - причем с большим отрывом.
A20: Это может говорить о том, что загрязнение почв там происходит наиболее радикально.
I21: Дополнительная таблица показывает, что в Восточно-Казахстанской области
I22: наиболее сильное загрязнение почв просиходит в г. Риддер.

Sheet metadata_water_pollution
B1: Случаи высокого загрязнения и экстремально высокого загрязнения поверхностных вод РК
A3: № | B3: Наименование в таблице | C3: Значение
A4: 1 | B4: region | C4: область
A5: 2 | B5: city | C5: населенный пункт
A6: 3 | B6: water_body | C6: наименование водного объекта, область, пункт наблюдения, створ
A7: 4 | B7: HPE_EHE | C7: кол-во случаев ВЗ и ЭВЗ
A8: 5 | B8: date | C8: год, число, месяц отбора проб
A9: 6 | B9: date_analysis | C9: год, число, месяц проведения анализа
A10: 7 | B10: substance_name | C10: наименование загрязняющего вещества
A11: 8 | B11: unit_measure | C11: единица измерения
A12: 9 | B12: concentration | C12: концентрия, мг/дм3
A13: 10 | B13: year | C13: год

Sheet metadata_soil_pollution
B1: Превышение предельно допустимой концентрации свинца и хрома в почвах регионов
A3: № | B3: Наименование в таблице | C3: Значение
A4: 1 | B4: region | C4: область
A5: 2 | B5: city | C5: населенный пункт
A6: 3 | B6: exceedance_MPC | C6: кратность превышения предельно допустимой концентрации (ПДК)
A7: 4 | B7: year | C7: год

Sheet cancer_per_100
A1: region | B1: rural_incidence_per_100 | C1: urban_incidence_per_100 | D1: year
A2: Область Абай | B2: 220.9 | C2: 302.4 | D2: 2024
A3: Акмолинская | B3: 306.2 | C3: 217.8 | D3: 2024
A4: Актюбинская | B4: 273.3 | C4: 168.8 | D4: 2024
A5: Алматинская | B5: 146.1 | C5: 110.2 | D5: 2024
A6: Атырауская | B6: 163.7 | C6: 157.3 | D6: 2024
A7: Западно-Казахстанская | B7: 222 | C7: 244.2 | D7: 2024
A8: Жамбылская | B8: 110 | C8: 167.9 | D8: 2024
A9: Область Жетысу | B9: 209.7 | C9: 175.4 | D9: 2024
A10: Карагандинская | B10: 233.3 | C10: 353.5 | D10: 2024
A11: Костанайская | B11: 258.8 | C11: 352.7 | D11: 2024
A12: Кызылординская | B12: 68.2 | C12: 271.2 | D12: 2024
A13: Мангыстауская | B13: 87.3 | C13: 181.9 | D13: 2024
... A21: г. Шымкент | B21: 0 | C21: 122.3 | D21: 2024

Sheet cancer_rural_urban
A1: region | B1: SUM из rural_incidence_per_100
A2: Восточно-Казахстанская | B2: 355.2
A3: Северо-Казахстанская | B3: 330
A4: Акмолинская | B4: 306.2
A5: Актюбинская | B5: 273.3
A6: Костанайская | B6: 258.8
A7: Павлодарская | B7: 244.6
A8: Карагандинская | B8: 233.3
A9: Западно-Казахстанская | B9: 222
A10: Область Абай | B10: 220.9
A11: Область Жетысу | B11: 209.7
A12: Атырауская | B12: 163.7
A13: Алматинская | B13: 146.1
... A17: Кызылординская | B17: 68.2
A19: Анти-рейтинг по заболеваемости онкологией среди сельского населения.
E23: Анти-рейтинг по заболеваемости онкологией среди городского населения.

Sheet metadata_cancer_per 100
B1: ЗАБОЛЕВАЕМОСТЬ ЗЛОКАЧЕСТВЕННЫМИ НОВООБРАЗОВАНИЯМИ (на 100 000 человек соответствующего населения)
A3: № | B3: Наименование в таблице | C3: Значение
A4: 1 | B4: region | C4: регион
A5: 2 | B5: rural_incidence_per_100 | C5: количество заболеваний на 100000 человек сельского населения
A6: 3 | B6: urban_incidence_per_100 | C6: количество заболеваний на 100000 человек городского населения
A7: 4 | B7: year | C7: год

Sheet types_cancer
A1: localization | B1: abs_numbers | C1: stage I-II-III | D1: stage IV | E1: year
A2: губа | B2: 111 | C2: 99.1 | D2: 0.9 | E2: 2024
A3: пищевод | B3: 1150 | C3: 92.6 | D3: 7.4 | E3: 2024
A4: желудок | B4: 2843 | C4: 82.7 | D4: 17.2 | E4: 2024
A5: прямая кишка | B5: 1781 | C5: 88.8 | D5: 11.2 | E5: 2024
A6: гортань | B6: 370 | C6: 88.9 | D6: 11.1 | E6: 2024
A7: трахея, бронхи, легкие | B7: 3707 | C7: 73.5 | D7: 26.5 | E7: 2024
A8: кожа | B8: 3862 | C8: 99.5 | D8: 0.3 | E8: 2024
A9: молочная железа | B9: 5577 | C9: 95.7 | D9: 4.2 | E9: 2024
A10: шейка матки | B10: 1897 | C10: 96.8 | D10: 3.2 | E10: 2024
A11: злокачественные новообразования лимфатических тканей | B11: 1029 | C11: 50.9 | D11: 8 | E11: 2024

Sheet localization_cancer
A1: localization | B1: SUM из stage I-II-III | C1: SUM из stage IV
A2: кожа | B2: 99.5 | C2: 0.3
A3: губа | B3: 99.1 | C3: 0.9
A4: шейка матки | B4: 96.8 | C4: 3.2
A5: молочная железа | B5: 95.7 | C5: 4.2
A6: пищевод | B6: 92.6 | C6: 7.4
A7: гортань | B7: 88.9 | C7: 11.1
A8: прямая кишка | B8: 88.8 | C8: 11.2
A9: желудок | B9: 82.7 | C9: 17.2
A10: трахея, бронхи, легкие | B10: 73.5 | C10: 26.5
A11: злокачественные новообразования лимфатических тканей | B11: 50.9 | C11: 8
A13: Чаще всего в Казахстане болеют онкологией кожи, губы, шейки матки и молочной железы.
A14: При этом нельзя назвать эти локализации "лидерами", потому что все приведенные локализации не сильно отличаются по частоте выявления.
A15: Но можно сказать, что реже всего встречаются злокачественные новообразования лимфатических тканей.
A16: А онкологию трахеи, бронхов, легких и желудка чаще всего диагностируют только на последней стадии болезни.

Sheet metadata_types_cancer
B1: РАСПРЕДЕЛЕНИЕ БОЛЬНЫХ ЗЛОКАЧЕСТВЕННЫМИ НОВООБРАЗОВАНИЯМИ С ВПЕРВЫЕ В ЖИЗНИ УСТАНОВЛЕННЫМ ДИАГНОЗОМ ПО СТАДИЯМ
A3: № | B3: Наименование в таблице | C3: Значение
A4: 1 | B4: localization | C4: локализация новообразования
A5: 2 | B5: abs_numbers | C5: абсолютное число заболевших
A6: 3 | B6: stage I-II-III | C6: онкология на I-II-III стадии
A7: 4 | B7: stage IV | C7: онкология на IV стадии
A8: 5 | B8: year | C8: год

Sheet registered_cancer
A1: region | B1: patients_per_100 | C1: year
A2: Область Абай | B2: 1469.7 | C2: 2024
A3: Акмолинская | B3: 1347 | C3: 2024
A4: Актюбинская | B4: 974.9 | C4: 2024
A5: Алматинская | B5: 739.8 | C5: 2024
A6: Атырауская | B6: 757.6 | C6: 2024
A7: Западно-Казахстанская | B7: 1260.6 | C7: 2024
A8: Жамбылская | B8: 761 | C8: 2024
A9: Область Жетысу | B9: 1042.5 | C9: 2024
A10: Карагандинская | B10: 1884.8 | C10: 2024
A11: Костанайская | B11: 1792.8 | C11: 2024
A12: Кызылординская | B12: 694.8 | C12: 2024
A13: Мангыстауская | B13: 706.5 | C13: 2024
... A21: г. Шымкент | B21: 659.6 | C21: 2024

Sheet registered_anti_leaders
A1: region | B1: SUM из patients_per_100
A2: Северо-Казахстанская | B2: 2189
A3: Восточно-Казахстанская | B3: 2005.7 | D3: Представлен анти-рейтинг регионов по количеству больных онкологией,
A4: Карагандинская | B4: 1884.8 | D4: стоящих на диспансерном учете.
A5: Павлодарская | B5: 1838.9
A6: Костанайская | B6: 1792.8
A7: г. Алматы | B7: 1489.9 | D7: region | E7: SUM из patients_per_100
A8: Область Абай | B8: 1469.7 | D8: Северо-Казахстанская | E8: 2189
A9: Акмолинская | B9: 1347 | D9: Восточно-Казахстанская | E9: 2005.7
A10: Западно-Казахстанская | B10: 1260.6 | D10: Карагандинская | E10: 1884.8
A11: Область Улытау | B11: 1134.7 | D11: Павлодарская | E11: 1838.9
A12: г. Астана | B12: 1102 | D12: Костанайская | E12: 1792.8
A13: Область Жетысу | B13: 1042.5 | D13: г. Алматы | E13: 1489.9
A14: Актюбинская | B14: 974.9 | D14: Область Абай | E14: 1469.7
A15: Жамбылская | B15: 761 | D15: Акмолинская | E15: 1347
A16: Атырауская | B16: 757.6 | D16: Западно-Казахстанская | E16: 1260.6
A17: Алматинская | B17: 739.8 | D17: Область Улытау | E17: 1134.7
A18: Мангыстауская | B18: 706.5
A19: Кызылординская | B19: 694.8
A20: г. Шымкент | B20: 659.6
A21: Туркестанская | B21: 495.4

Sheet metadata_registered_cancer 
B1: КОНТИНГЕНТЫ БОЛЬНЫХ ЗЛОКАЧЕСТВЕННЫМИ НОВООБРАЗОВАНИЯМИ, СОСТОЯЩИЕ НА ДИСПАНСЕРНОМ УЧЕТЕ НА КОНЕЦ ОТЧЕТНОГО ГОДА
A3: № | B3: Наименование в таблице | C3: Значение
A4: 1 | B4: region | C4: область
A5: 2 | B5: patients_per_100 | C5: число больных злокачественными новообразованиями. состоящих на учете на конец соответствующего года, на 100000 человек населения
A6: 3 | B6: year | C6: год

Sheet death_rate
A1: region | B1: death_per_100 | C1: year
A2: Область Абай | B2: 114.7 | C2: 2024
A3: Акмолинская | B3: 87.6 | C3: 2024
A4: Актюбинская | B4: 52.9 | C4: 2024
A5: Алматинская | B5: 47.4 | C5: 2024
A6: Атырауская | B6: 44.2 | C6: 2024
A7: Западно-Казахстанская | B7: 83.9 | C7: 2024
A8: Жамбылская | B8: 55.4 | C8: 2024
A9: Область Жетысу | B9: 51.1 | C9: 2024
A10: Карагандинская | B10: 77.7 | C10: 2024
A11: Костанайская | B11: 79.2 | C11: 2024
A12: Кызылординская | B12: 48.7 | C12: 2024
A13: Мангыстауская | B13: 45.2 | C13: 2024
... A21: г. Шымкент | B21: 47.4 | C21: 2024

Sheet death_anti_leaders
D2: Показан уровень смертности от онкологии в регионах.
D3: Примечательно, что по смертности лидирует Область Абай, хотя в остальных рейтингах по онкологии она занимает позицию в середине.

Sheet metadata_death_rate 
B1: СМЕРТНОСТЬ ОТ ЗЛОКАЧЕСТВЕННЫХ НОВООБРАЗОВАНИЙ
A3: № | B3: Наименование в таблице | C3: Значение
A4: 1 | B4: region | C4: область
A5: 2 | B5: death_per_100 | C5: число умерших от злокачественных новообразований на 100000 человек
A6: 3 | B6: year | C6: год

Sheet medical_care_availability
A1: region | B1: oncology clinics | C1: oncologists_per_100 | D1: oncology beds_per_100 | E1: year
A2: Область Абай | B2: 14 | C2: 1 | D2: 2.2 | E2: 2024
A3: Акмолинская | B3: 14 | C3: 0.4 | D3: 1.5 | E3: 2024
A4: Актюбинская | B4: 20 | C4: 0.7 | D4: 1.4 | E4: 2024
A5: Алматинская | B5: 16 | C5: 0.3 | D5: 0.3 | E5: 2024
A6: Атырауская | B6: 14 | C6: 0.4 | D6: 1.4 | E6: 2024
A7: Западно-Казахстанская | B7: 25 | C7: 0.4 | D7: 1.8 | E7: 2024
A8: Жамбылская | B8: 17 | C8: 0.4 | D8: 0.9 | E8: 2024
A9: Область Жетысу | B9: 13 | C9: 0.4 | D9: 2.4 | E9: 2024
A10: Карагандинская | B10: 23 | C10: 0.8 | D10: 1.7 | E10: 2024
A11: Костанайская | B11: 24 | C11: 0.3 | D11: 2.2 | E11: 2024
A12: Кызылординская | B12: 20 | C12: 0.4 | D12: 1.3 | E12: 2024
A13: Мангыстауская | B13: 10 | C13: 0.5 | D13: 0.9 | E13: 2024
... A21: г. Шымкент | B21: 24 | C21: 0.5 | D21: 1.7 | E21: 2024

Sheet medical_care_statistics
F3: Показана обеспеченность населения медицинской помощью.
F4: Интересно, что в Туркестанской области много онкологических кабинетов,
F5: но при этом наблюдается острая нехватка врачей-онкологов.

Sheet metadata_medical_care_availabil
B1: ОБЕСПЕЧЕННОСТЬ НАСЕЛЕНИЯ ОНКОЛОГИЧЕСКОЙ ПОМОЩЬЮ
A3: № | B3: Наименование в таблице | C3: Значение
A4: 1 | B4: region | C4: область
A5: 2 | B5: oncology clinics | C5: количество онкологических кабинетов
A6: 3 | B6: oncologists_per_100 | C6: врачи-онкологи на 100000 человек населения
A7: 4 | B7: oncology beds_per_100 | C7: онкологические койки на 100000 человек населения
A8: 5 | B8: year | C8: год

Sheet city_to_region
A1: region | B1: citiy
A2: Область Абай | B2: г. Аягоз
A3: Область Абай | B3: г. Абай
A4: Область Абай | B4: пос. Ауэзов
A5: Область Абай | B5: г. Семей
A6: Акмолинская | B6: с. Коргалжын
A7: Акмолинская | B7: с. Р. Кошкарбаева
A8: Акмолинская | B8: г. Атбасар
A9: Акмолинская | B9: с. Покровка
A10: Акмолинская | B10: г. Щучинск
A11: Акмолинская | B11: г. Степногорск
A12: Акмолинская | B12: СКФМ Боровое
... A96: г. Шымкент | B96: г. Шымкент
